Workbook

Sheet Students
A1: Name | B1: Email | C1: Campus | D1: Specialization | E1: Soft Skills Evaluation | F1: Technical Evaluation | G1: Soft Skills Score | H1: Technical Score | I1: GD Score | J1: Total Score Overall | K1: Total Score SS + GD
A2: Aakriti Tandon | B2: akriti.tandon@indiraisbs.ac.in | C2: ISBS PGDM | D2: HR | E2: =IF(A2<>"", IF(COUNTIF(Technical_Evaluations!C:C, A2), "Present", "Absent"), "") -> Present | F2: =IF(A2<>"", IF(COUNTIF(Technical_Evaluations!C:C, A2), "Present", "Absent"), "") -> Present | G2: =IFERROR(VLOOKUP(A2, SoftSkills_Evaluations!C:L, 8, FALSE), "") -> 52 | H2: =IFERROR(VLOOKUP(A2, Technical_Evaluations!C:L, 7, FALSE), "") -> 64.2 | I2: =IFERROR(VLOOKUP(A2, 'GD Evaluations'!A:G, 7, FALSE), "") -> 48 | J2: =SUM(G2:I2)/3 -> 54.733333 | K2: =(G2+I2)/2 -> 50
A3: Abha Patil | B3: abha.patil24@indiraiimp.edu.in | C3: IIMP | D3: MKT | E3: =IF(A3<>"", IF(COUNTIF(Technical_Evaluations!C:C, A3), "Present", "Absent"), "") -> Present | F3: =IF(A3<>"", IF(COUNTIF(Technical_Evaluations!C:C, A3), "Present", "Absent"), "") -> Present | G3: =IFERROR(VLOOKUP(A3, SoftSkills_Evaluations!C:L, 8, FALSE), "") -> 66 | H3: =IFERROR(VLOOKUP(A3, Technical_Evaluations!C:L, 7, FALSE), "") -> 80 | I3: =IFERROR(VLOOKUP(A3, 'GD Evaluations'!A:G, 7, FALSE), "") -> 73 | J3: =SUM(G3:I3)/3 -> 73 | K3: =(G3+I3)/2 -> 69.5
A4: Abhijit Dipak Wagh | B4: abhijit.wagh24@indiraiimp.edu.in | C4: IIMP | D4: MKT | E4: =IF(A4<>"", IF(COUNTIF(Technical_Evaluations!C:C, A4), "Present", "Absent"), "") -> Absent | F4: =IF(A4<>"", IF(COUNTIF(Technical_Evaluations!C:C, A4), "Present", "Absent"), "") -> Absent | G4: =IFERROR(VLOOKUP(A4, SoftSkills_Evaluations!C:L, 8, FALSE), "") | H4: =IFERROR(VLOOKUP(A4, Technical_Evaluations!C:L, 7, FALSE), "") | I4: =IFERROR(VLOOKUP(A4, 'GD Evaluations'!A:G, 7, FALSE), "") | J4: =SUM(G4:I4)/3 -> 0 | K4: =(G4+I4)/2 -> 0
A5: Abhishek Gajanan Deshpande | B5: abhishek.deshpande24@indiraiimp.edu.in | C5: IIMP | D5: FIN | E5: =IF(A5<>"", IF(COUNTIF(Technical_Evaluations!C:C, A5), "Present", "Absent"), "") -> Absent | F5: =IF(A5<>"", IF(COUNTIF(Technical_Evaluations!C:C, A5), "Present", "Absent"), "") -> Absent | G5: =IFERROR(VLOOKUP(A5, SoftSkills_Evaluations!C:L, 8, FALSE), "") | H5: =IFERROR(VLOOKUP(A5, Technical_Evaluations!C:L, 7, FALSE), "") | I5: =IFERROR(VLOOKUP(A5, 'GD Evaluations'!A:G, 7, FALSE), "") | J5: =SUM(G5:I5)/3 -> 0 | K5: =(G5+I5)/2 -> 0
A6: Aditi Nene | B6: aditi.nene24@indiraiimp.edu.in | C6: IIMP | D6: MKT | E6: =IF(A6<>"", IF(COUNTIF(Technical_Evaluations!C:C, A6), "Present", "Absent"), "") -> Absent | F6: =IF(A6<>"", IF(COUNTIF(Technical_Evaluations!C:C, A6), "Present", "Absent"), "") -> Absent | G6: =IFERROR(VLOOKUP(A6, SoftSkills_Evaluations!C:L, 8, FALSE), "") | H6: =IFERROR(VLOOKUP(A6, Technical_Evaluations!C:L, 7, FALSE), "") | I6: =IFERROR(VLOOKUP(A6, 'GD Evaluations'!A:G, 7, FALSE), "") | J6: =SUM(G6:I6)/3 -> 0 | K6: =(G6+I6)/2 -> 0
A7: Aditi Sunil Nade | B7: aditi.nade24@indiraiimp.edu.in | C7: IIMP | D7: HR | E7: =IF(A7<>"", IF(COUNTIF(Technical_Evaluations!C:C, A7), "Present", "Absent"), "") -> Present | F7: =IF(A7<>"", IF(COUNTIF(Technical_Evaluations!C:C, A7), "Present", "Absent"), "") -> Present | G7: =IFERROR(VLOOKUP(A7, SoftSkills_Evaluations!C:L, 8, FALSE), "") -> 96 | H7: =IFERROR(VLOOKUP(A7, Technical_Evaluations!C:L, 7, FALSE), "") -> 89.4 | I7: =IFERROR(VLOOKUP(A7, 'GD Evaluations'!A:G, 7, FALSE), "") -> 51 | J7: =SUM(G7:I7)/3 -> 78.8 | K7: =(G7+I7)/2 -> 73.5
A8: Ajay Rajaram Sagar | B8: ajay.sagar24@indiraiimp.edu.in | C8: IIMP | D8: MKT | E8: =IF(A8<>"", IF(COUNTIF(Technical_Evaluations!C:C, A8), "Present", "Absent"), "") -> Present | F8: =IF(A8<>"", IF(COUNTIF(Technical_Evaluations!C:C, A8), "Present", "Absent"), "") -> Present | G8: =IFERROR(VLOOKUP(A8, SoftSkills_Evaluations!C:L, 8, FALSE), "") -> 64.6 | H8: =IFERROR(VLOOKUP(A8, Technical_Evaluations!C:L, 7, FALSE), "") -> 55.2 | I8: =IFERROR(VLOOKUP(A8, 'GD Evaluations'!A:G, 7, FALSE), "") -> 66 | J8: =SUM(G8:I8)/3 -> 61.933333 | K8: =(G8+I8)/2 -> 65.3
A9: Akshada Shashikant Shahane | B9: akshadashahane@indiraicp.edu.in | C9: ICP | D9: FIN | E9: =IF(A9<>"", IF(COUNTIF(Technical_Evaluations!C:C, A9), "Present", "Absent"), "") -> Absent | F9: =IF(A9<>"", IF(COUNTIF(Technical_Evaluations!C:C, A9), "Present", "Absent"), "") -> Absent | G9: =IFERROR(VLOOKUP(A9, SoftSkills_Evaluations!C:L, 8, FALSE), "") | H9: =IFERROR(VLOOKUP(A9, Technical_Evaluations!C:L, 7, FALSE), "") | I9: =IFERROR(VLOOKUP(A9, 'GD Evaluations'!A:G, 7, FALSE), "") | J9: =SUM(G9:I9)/3 -> 0 | K9: =(G9+I9)/2 -> 0
A10: Amit Satish Bodake | B10: amit.bodake24@indiraiimp.edu.in | C10: IIMP | D10: MKT | E10: =IF(A10<>"", IF(COUNTIF(Technical_Evaluations!C:C, A10), "Present", "Absent"), "") -> Present | F10: =IF(A10<>"", IF(COUNTIF(Technical_Evaluations!C:C, A10), "Present", "Absent"), "") -> Present | G10: =IFERROR(VLOOKUP(A10, SoftSkills_Evaluations!C:L, 8, FALSE), "") -> 71.6 | H10: =IFERROR(VLOOKUP(A10, Technical_Evaluations!C:L, 7, FALSE), "") -> 51 | I10: =IFERROR(VLOOKUP(A10, 'GD Evaluations'!A:G, 7, FALSE), "") -> 50 | J10: =SUM(G10:I10)/3 -> 57.533333 | K10: =(G10+I10)/2 -> 60.8
A11: Aniruddha Krushna Hiwale | B11: aniruddha.hiwale@indiraisbs.edu.in | C11: ISBS | D11: MKT | E11: =IF(A11<>"", IF(COUNTIF(Technical_Evaluations!C:C, A11), "Present", "Absent"), "") -> Absent | F11: =IF(A11<>"", IF(COUNTIF(Technical_Evaluations!C:C, A11), "Present", "Absent"), "") -> Absent | G11: =IFERROR(VLOOKUP(A11, SoftSkills_Evaluations!C:L, 8, FALSE), "") | H11: =IFERROR(VLOOKUP(A11, Technical_Evaluations!C:L, 7, FALSE), "") | I11: =IFERROR(VLOOKUP(A11, 'GD Evaluations'!A:G, 7, FALSE), "") | J11: =SUM(G11:I11)/3 -> 0 | K11: =(G11+I11)/2 -> 0
A12: Anjali | B12: anjali.2426@indiraisbs.ac.in | C12: ISBS PGDM | D12: HR | E12: =IF(A12<>"", IF(COUNTIF(Technical_Evaluations!C:C, A12), "Present", "Absent"), "") -> Absent | F12: =IF(A12<>"", IF(COUNTIF(Technical_Evaluations!C:C, A12), "Present", "Absent"), "") -> Absent | G12: =IFERROR(VLOOKUP(A12, SoftSkills_Evaluations!C:L, 8, FALSE), "") | H12: =IFERROR(VLOOKUP(A12, Technical_Evaluations!C:L, 7, FALSE), "") | I12: =IFERROR(VLOOKUP(A12, 'GD Evaluations'!A:G, 7, FALSE), "") | J12: =SUM(G12:I12)/3 -> 0 | K12: =(G12+I12)/2 -> 0
A13: Ankita Sarode | B13: ankita.sarode24@indiraiimp.edu.in | C13: IIMP | D13: MKT | E13: =IF(A13<>"", IF(COUNTIF(Technical_Evaluations!C:C, A13), "Present", "Absent"), "") -> Absent | F13: =IF(A13<>"", IF(COUNTIF(Technical_Evaluations!C:C, A13), "Present", "Absent"), "") -> Absent | G13: =IFERROR(VLOOKUP(A13, SoftSkills_Evaluations!C:L, 8, FALSE), "") -> 80 | H13: =IFERROR(VLOOKUP(A13, Technical_Evaluations!C:L, 7, FALSE), "") | I13: =IFERROR(VLOOKUP(A13, 'GD Evaluations'!A:G, 7, FALSE), "") -> 82 | J13: =SUM(G13:I13)/3 -> 54 | K13: =(G13+I13)/2 -> 81
... A283: Saumyaa Pathak | B283: saumyaa.pathak@indiraisbs.ac.in | C283: ISBS PGDM | D283: MKT | E283: =IF(A283<>"", IF(COUNTIF(Technical_Evaluations!C:C, A283), "Present", "Absent"), "") -> Present | F283: =IF(A283<>"", IF(COUNTIF(Technical_Evaluations!C:C, A283), "Present", "Absent"), "") -> Present | G283: =IFERROR(VLOOKUP(A283, SoftSkills_Evaluations!C:L, 8, FALSE), "") -> 92.8 | H283: =IFERROR(VLOOKUP(A283, Technical_Evaluations!C:L, 7, FALSE), "") -> 79.8 | I283: =IFERROR(VLOOKUP(A283, 'GD Evaluations'!A:G, 7, FALSE), "") -> 64 | J283: =SUM(G283:I283)/3 -> 78.866667 | K283: =(G283+I283)/2 -> 78.4
A284: prathamesh dipak mehare | B284: prathamesh.mehare@indiraisbs.ac.in | C284: ISBS PGDM | D284: MKT | E284: =IF(A284<>"", IF(COUNTIF(Technical_Evaluations!C:C, A284), "Present", "Absent"), "") -> Absent | F284: =IF(A284<>"", IF(COUNTIF(Technical_Evaluations!C:C, A284), "Present", "Absent"), "") -> Absent | G284: =IFERROR(VLOOKUP(A284, SoftSkills_Evaluations!C:L, 8, FALSE), "") | H284: =IFERROR(VLOOKUP(A284, Technical_Evaluations!C:L, 7, FALSE), "") | I284: =IFERROR(VLOOKUP(A284, 'GD Evaluations'!A:G, 7, FALSE), "")
E285: =IF(A285<>"", IF(COUNTIF(Technical_Evaluations!C:C, A285), "Present", "Absent"), "") | F285: =IF(A285<>"", IF(COUNTIF(Technical_Evaluations!C:C, A285), "Present", "Absent"), "") | G285: =IFERROR(VLOOKUP(A285, SoftSkills_Evaluations!C:L, 8, FALSE), "") | I285: =IFERROR(VLOOKUP(A285, 'GD Evaluations'!A:G, 7, FALSE), "")
F286: =IF(A286<>"", IF(COUNTIF(Technical_Evaluations!C:C, A286), "Present", "Absent"), "") | G286: =IFERROR(VLOOKUP(A286, SoftSkills_Evaluations!C:L, 8, FALSE), "") | I286: =IFERROR(VLOOKUP(A286, 'GD Evaluations'!A:G, 7, FALSE), "")
F287: =IF(A287<>"", IF(COUNTIF(Technical_Evaluations!C:C, A287), "Present", "Absent"), "") | G287: =IFERROR(VLOOKUP(A287, SoftSkills_Evaluations!C:L, 8, FALSE), "") | I287: =IFERROR(VLOOKUP(A287, 'GD Evaluations'!A:G, 7, FALSE), "")
F288: =IF(A288<>"", IF(COUNTIF(Technical_Evaluations!C:C, A288), "Present", "Absent"), "") | G288: =IFERROR(VLOOKUP(A288, SoftSkills_Evaluations!C:L, 8, FALSE), "") | I288: =IFERROR(VLOOKUP(A288, 'GD Evaluations'!A:G, 7, FALSE), "")
F289: =IF(A289<>"", IF(COUNTIF(Technical_Evaluations!C:C, A289), "Present", "Absent"), "") | G289: =IFERROR(VLOOKUP(A289, SoftSkills_Evaluations!C:L, 8, FALSE), "") | I289: =IFERROR(VLOOKUP(A289, 'GD Evaluations'!A:G, 7, FALSE), "")
F290: =IF(A290<>"", IF(COUNTIF(Technical_Evaluations!C:C, A290), "Present", "Absent"), "") | G290: =IFERROR(VLOOKUP(A290, SoftSkills_Evaluations!C:L, 8, FALSE), "") | I290: =IFERROR(VLOOKUP(A290, 'GD Evaluations'!A:G, 7, FALSE), "")
F291: =IF(A291<>"", IF(COUNTIF(Technical_Evaluations!C:C, A291), "Present", "Absent"), "") | G291: =IFERROR(VLOOKUP(A291, SoftSkills_Evaluations!C:L, 8, FALSE), "") | I291: =IFERROR(VLOOKUP(A291, 'GD Evaluations'!A:G, 7, FALSE), "")
F292: =IF(A292<>"", IF(COUNTIF(Technical_Evaluations!C:C, A292), "Present", "Absent"), "") | G292: =IFERROR(VLOOKUP(A292, SoftSkills_Evaluations!C:L, 8, FALSE), "") | I292: =IFERROR(VLOOKUP(A292, 'GD Evaluations'!A:G, 7, FALSE), "")
F293: =IF(A293<>"", IF(COUNTIF(Technical_Evaluations!C:C, A293), "Present", "Absent"), "") | G293: =IFERROR(VLOOKUP(A293, SoftSkills_Evaluations!C:L, 8, FALSE), "") | I293: =IFERROR(VLOOKUP(A293, 'GD Evaluations'!A:G, 7, FALSE), "")
F294: =IF(A294<>"", IF(COUNTIF(Technical_Evaluations!C:C, A294), "Present", "Absent"), "") | G294: =IFERROR(VLOOKUP(A294, SoftSkills_Evaluations!C:L, 8, FALSE), "") | I294: =IFERROR(VLOOKUP(A294, 'GD Evaluations'!A:G, 7, FALSE), "")
F295: =IF(A295<>"", IF(COUNTIF(Technical_Evaluations!C:C, A295), "Present", "Absent"), "") | G295: =IFERROR(VLOOKUP(A295, SoftSkills_Evaluations!C:L, 8, FALSE), "") | I295: =IFERROR(VLOOKUP(A295, 'GD Evaluations'!A:G, 7, FALSE), "")
F296: =IF(A296<>"", IF(COUNTIF(Technical_Evaluations!C:C, A296), "Present", "Absent"), "") | G296: =IFERROR(VLOOKUP(A296, SoftSkills_Evaluations!C:L, 8, FALSE), "") | I296: =IFERROR(VLOOKUP(A296, 'GD Evaluations'!A:G, 7, FALSE), "")
F297: =IF(A297<>"", IF(COUNTIF(Technical_Evaluations!C:C, A297), "Present", "Absent"), "") | G297: =IFERROR(VLOOKUP(A297, SoftSkills_Evaluations!C:L, 8, FALSE), "") | I297: =IFERROR(VLOOKUP(A297, 'GD Evaluations'!A:G, 7, FALSE), "")
G298: =IFERROR(VLOOKUP(A298, SoftSkills_Evaluations!C:L, 8, FALSE), "") | I298: =IFERROR(VLOOKUP(A298, 'GD Evaluations'!A:G, 7, FALSE), "")
G299: =IFERROR(VLOOKUP(A299, SoftSkills_Evaluations!C:L, 8, FALSE), "") | I299: =IFERROR(VLOOKUP(A299, 'GD Evaluations'!A:G, 7, FALSE), "")
G300: =IFERROR(VLOOKUP(A300, SoftSkills_Evaluations!C:L, 8, FALSE), "") | I300: =IFERROR(VLOOKUP(A300, 'GD Evaluations'!A:G, 7, FALSE), "")
G301: =IFERROR(VLOOKUP(A301, SoftSkills_Evaluations!C:L, 8, FALSE), "") | I301: =IFERROR(VLOOKUP(A301, 'GD Evaluations'!A:G, 7, FALSE), "")
G302: =IFERROR(VLOOKUP(A302, SoftSkills_Evaluations!C:L, 8, FALSE), "") | I302: =IFERROR(VLOOKUP(A302, 'GD Evaluations'!A:G, 7, FALSE), "")
G303: =IFERROR(VLOOKUP(A303, SoftSkills_Evaluations!C:L, 8, FALSE), "") | I303: =IFERROR(VLOOKUP(A303, 'GD Evaluations'!A:G, 7, FALSE), "")
G304: =IFERROR(VLOOKUP(A304, SoftSkills_Evaluations!C:L, 8, FALSE), "") | I304: =IFERROR(VLOOKUP(A304, 'GD Evaluations'!A:G, 7, FALSE), "")
G305: =IFERROR(VLOOKUP(A305, SoftSkills_Evaluations!C:L, 8, FALSE), "") | I305: =IFERROR(VLOOKUP(A305, 'GD Evaluations'!A:G, 7, FALSE), "")
G306: =IFERROR(VLOOKUP(A306, SoftSkills_Evaluations!C:L, 8, FALSE), "") | I306: =IFERROR(VLOOKUP(A306, 'GD Evaluations'!A:G, 7, FALSE), "")
G307: =IFERROR(VLOOKUP(A307, SoftSkills_Evaluations!C:L, 8, FALSE), "") | I307: =IFERROR(VLOOKUP(A307, 'GD Evaluations'!A:G, 7, FALSE), "")
G308: =IFERROR(VLOOKUP(A308, SoftSkills_Evaluations!C:L, 8, FALSE), "") | I308: =IFERROR(VLOOKUP(A308, 'GD Evaluations'!A:G, 7, FALSE), "")
G309: =IFERROR(VLOOKUP(A309, SoftSkills_Evaluations!C:L, 8, FALSE), "") | I309: =IFERROR(VLOOKUP(A309, 'GD Evaluations'!A:G, 7, FALSE), "")
...

Sheet GD Evaluations
A1: Student Name | B1: Opening | C1: Speaking | D1: Teamwork | E1: Engagement | F1: Closing | G1: Total Score | H1: Remarks
A2: Shreyash Hukkeri | B2: 19 | C2: 16 | D2: 16 | E2: 16 | F2: 17 | G2: 84
A3: harshal chaudhari | B3: 17 | C3: 12 | D3: 16 | E3: 16 | F3: 20 | G3: 81
A4: Utkarsh Satish Thorat | B4: 19 | C4: 19 | D4: 17 | E4: 20 | F4: 20 | G4: 95
A5: Roshni Kewlani | B5: 18 | C5: 19 | D5: 19 | E5: 20 | F5: 18 | G5: 94
A6: Aman Sandeep Punjabi | B6: 18 | C6: 12 | D6: 12 | E6: 16 | F6: 14 | G6: 72 | H6: interrupted the lady
A7: Rohini Ravindra Kamble | B7: 17 | C7: 16 | D7: 16 | E7: 16 | F7: 15 | G7: 80
A8: Diksha Mahadeo Kumbhare | B8: 17 | C8: 17 | D8: 16 | E8: 16 | F8: 15 | G8: 81
A9: khushi maru | B9: 14 | C9: 14 | D9: 16 | E9: 12 | F9: 13 | G9: 69
A10: Soham Choudhary | B10: 14 | C10: 12 | D10: 12 | E10: 12 | F10: 12 | G10: 62
A11: Chandrashekhar Rao | B11: 19 | C11: 20 | D11: 20 | E11: 20 | F11: 20 | G11: 99
A12: Uddesh Anil Panpaliya | B12: 18 | C12: 14 | D12: 16 | E12: 17 | F12: 20 | G12: 85
A13: Ishwar Rajendra Vyas | B13: 19 | C13: 16 | D13: 18 | E13: 16 | F13: 18 | G13: 87
A14: yatish nandkumar mudaliyar | B14: 12 | C14: 12 | D14: 12 | E14: 12 | F14: 9 | G14: 57
A15: swaleha paliwala | B15: 13 | C15: 12 | D15: 12 | E15: 12 | F15: 9 | G15: 58
A16: Onkar Sanjay Khandade | B16: 13 | C16: 12 | D16: 12 | E16: 11 | F16: 3 | G16: 51
A17: Dhriti Sahu | B17: 15 | C17: 16 | D17: 12 | E17: 12 | F17: 9 | G17: 64
A18: Tanishq Chandrakant Rathod | B18: 13 | C18: 12 | D18: 12 | E18: 13 | F18: 9 | G18: 59
... A35: Rohan Mirkale | B35: 12 | C35: 11 | D35: 12 | E35: 11 | F35: 3 | G35: 49
A36: Neha Jadhav | B36: 14 | C36: 16 | D36: 11 | E36: 12 | F36: 14 | G36: 67 | H36: More impact needed.
A37: LUMAKSHINI GENDLAL BHIOGADE | B37: 12 | C37: 12 | D37: 10 | E37: 11 | F37: 12 | G37: 57 | H37: Needs to be more impactful.
A38: Rasika Rajendra Gawali | B38: 13 | C38: 12 | D38: 12 | E38: 11 | F38: 13 | G38: 61 | H38: Be more proactive
A39: Piyush Rajendra Jadhav | B39: 13 | C39: 15 | D39: 9 | E39: 13 | F39: 17 | G39: 67 | H39: Speaks well but can work on Pronunciations, summarised with out asking.
A40: Aditi Sunil Nade | B40: 8 | C40: 11 | D40: 8 | E40: 11 | F40: 13 | G40: 51 | H40: Needs to be more impactful.
A41: Yash Abhay Bhagat | B41: 10 | C41: 8 | D41: 6 | E41: 7 | F41: 8 | G41: 39 | H41: Speaks fast, slow down for impact.
A42: Sakshi Sanjay Gawande | B42: 11 | C42: 11 | D42: 8 | E42: 10 | F42: 15 | G42: 55 | H42: Speak more elaboratively during the discussion.
A43: Harsh Shivhare | B43: 8 | C43: 8 | D43: 8 | E43: 9 | F43: 8 | G43: 41 | H43: Needs to speak more impactfully, proactively.
A44: Hrishikesh Mali | B44: 10 | C44: 10 | D44: 8 | E44: 13 | F44: 15 | G44: 56 | H44: Needs to be more impactful in communication skills.
A45: Prathamesh Parik | B45: 0 | C45: 6 | D45: 6 | E45: 6 | F45: 5 | G45: 23 | H45: Needs to be more prepared, proactive in participation.
A46: Atharva Mahesh Babhulgaonkar | B46: 15 | C46: 12 | D46: 11 | E46: 12 | F46: 9 | G46: 59
A47: Pawan Bhimdev Atole | B47: 14 | C47: 12 | D47: 13 | E47: 16 | F47: 9 | G47: 64
A48: Shubham Annasaheb Khatik | B48: 12 | C48: 12 | D48: 12 | E48: 16 | F48: 9 | G48: 61
A49: Janhavi Mahadeo Chaware | B49: 13 | C49: 13 | D49: 16 | E49: 14 | F49: 12 | G49: 68
A50: Saumyaa Pathak | B50: 14 | C50: 14 | D50: 12 | E50: 15 | F50: 9 | G50: 64
A51: Kishor Vaishnav | B51: 12 | C51: 11 | D51: 12 | E51: 12 | F51: 6 | G51: 53
A52: Emmanuel Suresh Mahure | B52: 16 | C52: 14 | D52: 13 | E52: 15 | F52: 9 | G52: 67
A53: Baswraj Bhimrao Biradar | B53: 10 | C53: 10 | D53: 12 | E53: 10 | F53: 9 | G53: 51
A54: Vyankatesh Santosh Dharmal | B54: 4 | C54: 4 | D54: 4 | E54: 4 | F54: 3 | G54: 19
A55: Omkar Arun Mhaske | B55: 17 | C55: 12 | D55: 12 | E55: 20 | F55: 16 | G55: 77
A56: Ajay Rajaram Sagar | B56: 15 | C56: 14 | D56: 6 | E56: 13 | F56: 18 | G56: 66
...

Sheet Technical_Evaluations
A1: Timestamp | B1: Interviewer | C1: Student | D1: Intro | E1: Intern | F1: Domain | G1: Situational | H1: Industry | I1: Total | J1: Campus | K1: Spec | L1: Remarks
A2: 45930.457 | B2: aishwaryakalyanshetti@gmail.com | C2: Gaurav Ashok Pawar | D2: 13.2 | E2: 12 | F2: 27.2 | G2: 14.4 | H2: 8 | I2: 74.8 | J2: IIMP | K2: FIN | L2: Needs to study more about the companies, what they do and why you are interested. Keep upto date about the current happenings in the industry. Detailed study about projects done.
A3: 45930.465 | B3: aishwaryakalyanshetti@gmail.com | C3: Bhavesh Dilip Jagtap | D3: 12 | E3: 12 | F3: 25.6 | G3: 18.8 | H3: 12 | I3: 80.4 | J3: IIMP | K3: FIN | L3: Answered well. Just be more confident while answering.
A4: 45930.475 | B4: aishwaryakalyanshetti@gmail.com | C4: SONALI SOMNATH GAIKAR | D4: 12 | E4: 15 | F4: 35 | G4: 20 | H4: 15 | I4: 97 | J4: ISBS | K4: FIN | L4: Great interview.
A5: 45930.482 | B5: aishwaryakalyanshetti@gmail.com | C5: Dhruv Jaiswal | D5: 11.2 | E5: 9 | F5: 19.8 | G5: 16 | H5: 9 | I5: 65 | J5: IIMP- PGDM | K5: Finance | L5: Need more clarity wrt your future and where exactly you want to be after pgdm. Study about companies and roles they offer in the area of your interest. Dream role n dream company were contradicting. Clarity in thoughts needed.
A6: 45930.498 | B6: aishwaryakalyanshetti@gmail.com | C6: Nikita Sharma | D6: 15 | E6: 12 | F6: 33.4 | G6: 20 | H6: 12 | I6: 92.4 | J6: ISBS PGDM | K6: FIN | L6: Great!
A7: 45930.498 | B7: aishwaryakalyanshetti@gmail.com | C7: Nikita Sharma | D7: 15 | E7: 12 | F7: 33.4 | G7: 20 | H7: 12 | I7: 92.4 | J7: ISBS PGDM | K7: FIN | L7: Great!
A8: 45930.51 | B8: aishwaryakalyanshetti@gmail.com | C8: Vaibhavi Samadhan Patil | D8: 13 | E8: 12 | F8: 23.6 | G8: 16 | H8: 9 | I8: 73.6 | J8: IIMP | K8: FIN | L8: Needs more clarity. Know everything thats on your CV thoroughly.
A9: 45930.511 | B9: aishwaryakalyanshetti@gmail.com | C9: shraddha pandurang kolhe | D9: 7.2 | E9: 9 | F9: 14 | G9: 12.4 | H9: 6 | I9: 48.6 | J9: IIMP | K9: FIN | L9: Needs alot of efforts. Re work on CV. Be thorough about everything thats on cv n recents industry insights.
A10: 45930.519 | B10: aishwaryakalyanshetti@gmail.com | C10: Soham Shashikant Chaudhari | D10: 12 | E10: 12 | F10: 33.4 | G10: 20 | H10: 12 | I10: 89.4 | J10: IIMP | K10: FIN | L10: Good CV good knowledge, good presentation. Study about the role you are applying/INTERESTED IN
A11: 45930.526 | B11: aishwaryakalyanshetti@gmail.com | C11: Kaustubh Pundlik Gawale | D11: 15 | E11: 12 | F11: 35 | G11: 20 | H11: 14 | I11: 96 | J11: ICP | K11: FIN | L11: Great
A12: 45930.53 | B12: aishwaryakalyanshetti@gmail.com | C12: Jay Sanjay Shimpi | D12: 10.8 | E12: 9 | F12: 19.4 | G12: 13.6 | H12: 7.2 | I12: 60 | J12: ICP | K12: FIN | L12: Needs a lot of knowledge in the domain. Work on your basics of finance, confidence and communication. Keep a tab of everything happening in investment banking.
A13: 45930.535 | B13: aishwaryakalyanshetti@gmail.com | C13: swaleha paliwala | D13: 15 | E13: 15 | F13: 35 | G13: 20 | H13: 10 | I13: 95 | J13: IIMP | K13: FIN | L13: Well done!
... A19: 45930.611 | B19: aishwaryakalyanshetti@gmail.com | C19: Vyankatesh Santosh Dharmal | D19: 12 | E19: 3 | F19: 11.2 | G19: 12 | H19: 6 | I19: 44.2 | J19: IIMP | K19: FIN | L19: Needs a lot of prep
A20: 45930.615 | B20: aishwaryakalyanshetti@gmail.com | C20: Tanishq Chandrakant Rathod | D20: 12 | E20: 10.6 | F20: 32.4 | G20: 20 | H20: 15 | I20: 90 | J20: IIMP | K20: FIN
A21: 45930.621 | B21: aishwaryakalyanshetti@gmail.com | C21: Mehul Kailas Tamboli | D21: 12 | E21: 10.6 | F21: 28 | G21: 20 | H21: 12 | I21: 82.6 | J21: ISBS PGDM | K21: FIN
A22: 45930.627 | B22: aishwaryakalyanshetti@gmail.com | C22: Ved M Vibhute | D22: 15 | E22: 12 | F22: 33.4 | G22: 20 | H22: 15 | I22: 95.4 | J22: ISBS PGDM | K22: FIN
A23: 45930.512 | B23: drtasneem.in@gmail.com | C23: Aakriti Tandon | D23: 8.8 | E23: 12 | F23: 24.2 | G23: 12 | H23: 7.2 | I23: 64.2 | J23: ISBS PGDM | K23: HR | L23: Resume Relevance is poor. needs to make resume more authentic with her personality. Domain knowledge of recruitment tested, that is good. Due to time constraint, could not explore more. Gave personal feedback in detail where she needs to improve
A24: 45930.539 | B24: drtasneem.in@gmail.com | C24: Aditi Sunil Nade | D24: 14 | E24: 15 | F24: 29.2 | G24: 17.2 | H24: 14 | I24: 89.4 | J24: IIMP | K24: HR | L24: Overall, she has good knowledge of HR and her logical with appropriate reasoning skills are good
A25: 45930.562 | B25: drtasneem.in@gmail.com | C25: Neha Jadhav | D25: 14 | E25: 15 | F25: 30.8 | G25: 12 | H25: 12 | I25: 83.8 | J25: IIMP | K25: HR | L25: Needs to make small correction in resume, rest is fine.
A26: 45930.614 | B26: drtasneem.in@gmail.com | C26: Rasika Rajendra Gawali | D26: 14.2 | E26: 15 | F26: 26.8 | G26: 12 | H26: 9 | I26: 77 | J26: IIMP | K26: HR | L26: She is aiming for HR generalist role which is a good start but over the period of time she needs to pick up the niche.
A27: 45930.633 | B27: drtasneem.in@gmail.com | C27: RUTUJA BADNAKHE | D27: 4.2 | E27: 3 | F27: 7 | G27: 4 | H27: 3 | I27: 21.2 | J27: ISBS PGDM | K27: HR | L27: She needs to be counselled. Domain knowledge is very poor. Lacks clarity of what she wants to do, what type of HR role she is inclined towards. Resume also needs to be updated. Lacks confidence.
A28: 45930.481 | B28: kuldeep.manhas@gmail.com | C28: Pratik Shivaji Ghuge | D28: 6 | E28: 6 | F28: 12.8 | G28: 6.8 | H28: 5 | I28: 36.6 | J28: IIMP | K28: MKT | L28: Need to do research about the industry, preparation was missing, work on the introduction part, keep the points ready for the Internship taken the key contributions, why you want to enter into a specific industry.
A29: 45930.494 | B29: kuldeep.manhas@gmail.com | C29: Rohan Mirkale | D29: 7.8 | E29: 7.4 | F29: 10.2 | G29: 9.2 | H29: 5.2 | I29: 39.8 | J29: ISBS PGDM | K29: MKT | L29: Introduction was Ok, Presentability was good, need to improve on communication, bring out connection between what you have done, Industry knowledge and role knowledge to improve, need to articulate and be clear and concise in what you talk
A30: 45930.505 | B30: kuldeep.manhas@gmail.com | C30: Baswraj Bhimrao Biradar | D30: 8 | E30: 9 | F30: 21 | G30: 12 | H30: 10.2 | I30: 60.2 | J30: IIMP | K30: MKT | L30: Good introduction, overall understanding of the role in sales is good, understand the key concepts, industry, energy level can be enhanced, need to sound more convincing, Have understanding but need to explain it more emphatically. Need to be concise with his answers
A31: 45930.518 | B31: kuldeep.manhas@gmail.com | C31: Krishna Manohar Gode | D31: 9 | E31: 10.4 | F31: 20.2 | G31: 12 | H31: 6 | I31: 57.6 | J31: ISBS | K31: MKT | L31: Good candidate, uses good body language, open, energetic, smile, positive intent, presentation is good, communicates effectively, connects well, just need to be more precise while presenting, need to listen well, presentability and grooming can be enhanced.
A32: 45930.533 | B32: kuldeep.manhas@gmail.com | C32: Rohini Ravindra Kamble | D32: 9 | E32: 10.4 | F32: 23.8 | G32: 12 | H32: 10 | I32: 65.2 | J32: ISBS | K32: MKT | L32: Good communication able to present concepts, domain and industry knowledge, introduction can be worked upon, need to be more calm and composed while presenting, Industry knowledge need to enhance
A33: 45930.543 | B33: kuldeep.manhas@gmail.com | C33: yatish nandkumar mudaliyar | D33: 7.8 | E33: 9 | F33: 19.6 | G33: 12 | H33: 8.2 | I33: 56.6 | J33: ISBS | K33: MKT | L33: Good presentability, able to communicate effectively, Introduction could be concise and better, understand the domain, need to understand more about the industry, trends and competition, body language could be improved.
A34: 45930.551 | B34: kuldeep.manhas@gmail.com | C34: Kishor Vaishnav | D34: 9 | E34: 9 | F34: 14 | G34: 8 | H34: 6 | I34: 46 | J34: ISBS PGDM | K34: MKT | L34: Good presentability, Introduction was OK, need to focus more on Industry and domain knowledge and present in a more persuasive manner
... A38: 45930.641 | B38: kuldeep.manhas@gmail.com | C38: KUSHAL RAMESHWAR MANKAR | D38: 12 | E38: 13.4 | F38: 30.8 | G38: 16 | H38: 12 | I38: 84.2 | J38: IIMP | K38: MKT | L38: Good presentation, his earlier experience is visible in his interview discussion, confidence, industry and domain knowledge is good, articulation and what to highlight is good, very good on most elements.
A39: 45930.458 | B39: prashant2k1@gmail.com | C39: Samrudh Dnyaneshwar Somase | D39: 12 | E39: 12 | F39: 25.2 | G39: 17.2 | H39: 14.2 | I39: 80.6 | J39: ICP | K39: MKT
A40: 45930.467 | B40: prashant2k1@gmail.com | C40: srushti sharad pawar | D40: 12 | E40: 12 | F40: 23.8 | G40: 17.6 | H40: 11.2 | I40: 76.6 | J40: IIMP | K40: MKT
A41: 45930.48 | B41: prashant2k1@gmail.com | C41: Gorgile rushikesh chandrakant | D41: 12 | E41: 10.6 | F41: 24.2 | G41: 13.2 | H41: 11 | I41: 71 | J41: IIMP | K41: MKT
A42: 45930.488 | B42: prashant2k1@gmail.com | C42: Vaibhav Gajanan Gayki | D42: 12.8 | E42: 12 | F42: 25.2 | G42: 13.2 | H42: 11.2 | I42: 74.4 | J42: IIMP- PGDM | K42: Marketing
A43: 45930.496 | B43: prashant2k1@gmail.com | C43: RAHUL SURESH VIDHATE | D43: 10.6 | E43: 10.6 | F43: 22.6 | G43: 12 | H43: 10 | I43: 65.8 | J43: ISBS PGDM | K43: MKT
A44: 45930.502 | B44: prashant2k1@gmail.com | C44: Sanskruti Tejkumar Gudadhe | D44: 13 | E44: 13.6 | F44: 24.2 | G44: 13.2 | H44: 10.2 | I44: 74.2 | J44: IIMP | K44: MKT
A45: 45930.509 | B45: prashant2k1@gmail.com | C45: Vaishnavi Shrikant Pahune | D45: 15 | E45: 12 | F45: 32.2 | G45: 17.6 | H45: 15 | I45: 91.8 | J45: IIMP | K45: MKT
A46: 45930.516 | B46: prashant2k1@gmail.com | C46: Rucha Santosh Dagale | D46: 10.2 | E46: 9 | F46: 21 | G46: 12 | H46: 6.8 | I46: 59 | J46: IIMP | K46: MKT
A47: 45930.524 | B47: prashant2k1@gmail.com | C47: Omkar Arun Mhaske | D47: 12 | E47: 10.6 | F47: 28 | G47: 16.4 | H47: 9.8 | I47: 76.8 | J47: IIMP | K47: MKT
A48: 45930.533 | B48: prashant2k1@gmail.com | C48: Uddesh Anil Panpaliya | D48: 9.8 | E48: 12 | F48: 28 | G48: 14.4 | H48: 13 | I48: 77.2 | J48: ISBS | K48: MKT
...

Sheet SoftSkills_Evaluations
A1: Timestamp | B1: Interviewer | C1: Student | D1: Intro | E1: Exp | F1: Body | G1: STAR | H1: Crisp | I1: Pers | J1: Total | K1: Campus | L1: Spec | M1: Domain | N1: Remarks
A2: 45930.405 | B2: tusharvkshirsagar@gmail.com | C2: Ankita Sarode | D2: 16 | E2: 12 | F2: 12 | G2: 16 | H2: 12 | I2: 12 | J2: 80 | K2: IIMP | L2: MKT
A3: 45930.453 | B3: deodeepa@gmail.com | C3: Vyankatesh Santosh Dharmal | D3: 5.4 | E3: 4.6 | F3: 5.2 | G3: 4 | H3: 5 | I3: 6 | J3: 30.2 | K3: IIMP | L3: FIN | N3: Required info missing
A4: 45930.462 | B4: smrutimehadia@gmail.com | C4: Amit Satish Bodake | D4: 13 | E4: 10.6 | F4: 11.2 | G4: 13.6 | H4: 11.2 | I4: 12 | J4: 71.6 | K4: IIMP | L4: MKT | N4: Overall good.
A5: 45930.467 | B5: deodeepa@gmail.com | C5: Pratik Vasant Ekale | D5: 13.6 | E5: 6 | F5: 12 | G5: 10.4 | H5: 9 | I5: 11 | J5: 62 | K5: IIMP | L5: FIN | N5: Gap of 2 years, graduation different domain.. elevator page ok, no STAR method used
A6: 45930.471 | B6: smrutimehadia@gmail.com | C6: Rajwardhan Mangesh Jadhav | D6: 14.6 | E6: 10.4 | F6: 12 | G6: 16 | H6: 12 | I6: 12 | J6: 77 | K6: IIMP | L6: MKT | N6: Good Expereince and right fit for organization. however needs to improve on resume writing and Body language. EYe contact was good
A7: 45930.475 | B7: madhumithapalani26@gmail.com | C7: Gaurav Ashok Pawar | D7: 11 | E7: 10.6 | F7: 6 | G7: 8 | H7: 6 | I7: 12 | J7: 53.6 | K7: IIMP | L7: FIN
A8: 45930.477 | B8: smrutimehadia@gmail.com | C8: Ajay Rajaram Sagar | D8: 14.4 | E8: 9 | F8: 9.2 | G8: 12 | H8: 9 | I8: 11 | J8: 64.6 | K8: IIMP | L8: MKT | N8: Needs to improve on rate of speech and STAR Method of Answer giving
A9: 45930.477 | B9: smrutimehadia@gmail.com | C9: Ajay Rajaram Sagar | D9: 14.4 | E9: 9 | F9: 9.2 | G9: 12 | H9: 9 | I9: 11 | J9: 64.6 | K9: IIMP | L9: MKT | N9: Needs to improve on rate of speech and STAR Method of Answer giving
A10: 45930.478 | B10: deodeepa@gmail.com | C10: Rohan Mirkale | D10: 9 | E10: 6 | F10: 7.2 | G10: 4 | H10: 6 | I10: 8 | J10: 40.2 | K10: ISBS PGDM | L10: MKT | N10: Need to work on spkg and language, but could be ok for sales profile/..
A11: 45930.478 | B11: tusharvkshirsagar@gmail.com | C11: RAHUL SURESH VIDHATE | D11: 10.4 | E11: 9 | F11: 9 | G11: 0 | H11: 9 | I11: 9 | J11: 46.4 | K11: ISBS PGDM | L11: MKT | N11: Overall seems to be good...can improve english communication,
A12: 45930.484 | B12: madhumithapalani26@gmail.com | C12: Bhavesh Dilip Jagtap | D12: 16 | E12: 13.4 | F12: 14.2 | G12: 20 | H12: 11.2 | I12: 11 | J12: 85.8 | K12: IIMP | L12: FIN
A13: 45930.484 | B13: smrutimehadia@gmail.com | C13: KUSHAL RAMESHWAR MANKAR | D13: 13.6 | E13: 12 | F13: 12 | G13: 16 | H13: 12 | I13: 12 | J13: 77.6 | K13: IIMP | L13: MKT | N13: Overall Good.
A14: 45930.489 | B14: smrutimehadia@gmail.com | C14: Krushna Rajesh Hage | D14: 13.4 | E14: 9 | F14: 9.2 | G14: 16 | H14: 12 | I14: 12 | J14: 71.6 | K14: IIMP | L14: MKT | N14: Need to work on Vocabulary. and also need to practice on interview questions.
A15: 45930.492 | B15: madhumithapalani26@gmail.com | C15: Vaibhavi Samadhan Patil | D15: 9.4 | E15: 9 | F15: 5 | G15: 8 | H15: 7 | I15: 8 | J15: 46.4 | K15: IIMP | L15: FIN
A16: 45930.494 | B16: tusharvkshirsagar@gmail.com | C16: Krishna Manohar Gode | D16: 16 | E16: 9 | F16: 12 | G16: 14.4 | H16: 9 | I16: 12 | J16: 72.4 | K16: ISBS | L16: MKT | N16: Good fit for role of marketing, great communication
A17: 45930.494 | B17: deodeepa@gmail.com | C17: Uddesh Anil Panpaliya | D17: 13.6 | E17: 10.4 | F17: 9 | G17: 12 | H17: 9.8 | I17: 10 | J17: 64.8 | K17: ISBS | L17: MKT | N17: Ground work ok, need some reality check
A18: 45930.496 | B18: smrutimehadia@gmail.com | C18: Sahil Dilip Tijare | D18: 10.4 | E18: 10.4 | F18: 8 | G18: 13.6 | H18: 11 | I18: 9 | J18: 62.4 | K18: IIMP | L18: MKT | N18: Need to work on STAR Methods based answering to questions
A19: 45930.501 | B19: madhumithapalani26@gmail.com | C19: swaleha paliwala | D19: 17.6 | E19: 13.4 | F19: 14.2 | G19: 17.6 | H19: 14.2 | I19: 13 | J19: 90 | K19: IIMP | L19: FIN
A20: 45930.502 | B20: tusharvkshirsagar@gmail.com | C20: srushti sharad pawar | D20: 13.6 | E20: 9 | F20: 10 | G20: 12 | H20: 9 | I20: 9 | J20: 62.6 | K20: IIMP | L20: MKT | N20: Good positive attitude.
A21: 45930.504 | B21: deodeepa@gmail.com | C21: Dhruv Jaiswal | D21: 8 | E21: 6 | F21: 7 | G21: 4 | H21: 6 | I21: 8 | J21: 39 | K21: IIMP- PGDM | L21: Finance | N21: Needs some examples. No STAR method
A22: 45930.505 | B22: madhumithapalani26@gmail.com | C22: shraddha pandurang kolhe | D22: 8 | E22: 6 | F22: 11.2 | G22: 6.4 | H22: 5 | I22: 8 | J22: 44.6 | K22: IIMP | L22: FIN
A23: 45930.506 | B23: smrutimehadia@gmail.com | C23: Onkar Sanjay Khandade | D23: 16 | E23: 10.4 | F23: 9 | G23: 13.6 | H23: 8 | I23: 8 | J23: 65 | K23: IIMP | L23: MKT
A24: 45930.512 | B24: smrutimehadia@gmail.com | C24: Nkhil Ganesh Patil | D24: 12 | E24: 9 | F24: 9 | G24: 9.6 | H24: 7.8 | I24: 7 | J24: 54.4 | K24: IIMP | L24: MKT | N24: He need to work on body language
A25: 45930.513 | B25: drtasneem.in@gmail.com | C25: Aakriti Tandon | D25: 9.2 | E25: 12 | F25: 5.8 | G25: 11.2 | H25: 4.8 | I25: 9 | J25: 52 | K25: ISBS PGDM | L25: HR | N25: needs to work on her energy and confidence level. be authentic and natural.
A26: 45930.515 | B26: madhumithapalani26@gmail.com | C26: Sakshi Ghanshyam Gandhi | D26: 4 | E26: 6 | F26: 7.6 | G26: 10.4 | H26: 6.8 | I26: 9 | J26: 43.8 | K26: IIMP | L26: FIN
A27: 45930.518 | B27: tusharvkshirsagar@gmail.com | C27: Pratik Shivaji Ghuge | D27: 12 | E27: 9 | F27: 9 | G27: 12 | H27: 9 | I27: 9 | J27: 60 | K27: IIMP | L27: MKT | N27: Good polite humble
A28: 45930.52 | B28: madhumithapalani26@gmail.com | C28: Vaishnavi Shrikant Pahune | D28: 12.2 | E28: 6 | F28: 10.8 | G28: 10.4 | H28: 12 | I28: 9 | J28: 60.4 | K28: IIMP | L28: MKT
A29: 45930.524 | B29: tusharvkshirsagar@gmail.com | C29: Vaibhav Gajanan Gayki | D29: 9.4 | E29: 9 | F29: 9 | G29: 12 | H29: 9 | I29: 9 | J29: 57.4 | K29: IIMP- PGDM | L29: Marketing | N29: English Communication - Tenses Weak, but candidate is good.
A30: 45930.524 | B30: smrutimehadia@gmail.com | C30: Vandana Sonawane | D30: 14.6 | E30: 10.6 | F30: 10.8 | G30: 16 | H30: 10 | I30: 12 | J30: 74 | K30: ISBS PGDM | L30: HR
A31: 45930.526 | B31: deodeepa@gmail.com | C31: Gorgile rushikesh chandrakant | D31: 13 | E31: 12 | F31: 10 | G31: 12 | H31: 9 | I31: 11 | J31: 67 | K31: IIMP | L31: MKT
A32: 45930.526 | B32: madhumithapalani26@gmail.com | C32: Sanskruti Tejkumar Gudadhe | D32: 13.6 | E32: 7.6 | F32: 13.8 | G32: 14.4 | H32: 9 | I32: 9 | J32: 67.4 | K32: IIMP | L32: MKT
A33: 45930.529 | B33: smrutimehadia@gmail.com | C33: Gauri Pawansing Thakur | D33: 13.4 | E33: 12 | F33: 10.2 | G33: 12 | H33: 12 | I33: 12 | J33: 71.6 | K33: ISBS PGDM | L33: HR | N33: Overall Good
A34: 45930.532 | B34: smrutimehadia@gmail.com | C34: SONALI SOMNATH GAIKAR | D34: 14.6 | E34: 12 | F34: 12 | G34: 16 | H34: 12 | I34: 11 | J34: 77.6 | K34: ISBS | L34: FIN | N34: Very Good overall
A35: 45930.533 | B35: madhumithapalani26@gmail.com | C35: RUTUJA BADNAKHE | D35: 15 | E35: 12 | F35: 7.8 | G35: 13.6 | H35: 9 | I35: 9 | J35: 66.4 | K35: ISBS PGDM | L35: HR
A36: 45930.537 | B36: drtasneem.in@gmail.com | C36: Aditi Sunil Nade | D36: 17.2 | E36: 15 | F36: 15 | G36: 20 | H36: 13.8 | I36: 15 | J36: 96 | K36: IIMP | L36: HR | N36: She is good in communication and confidence. Needs to work upon Resume, make it more impactful with her contribution to organization and eliminate generic job description and theory part
A37: 45930.538 | B37: deodeepa@gmail.com | C37: Baswraj Bhimrao Biradar | D37: 12 | E37: 9 | F37: 7.2 | G37: 12 | H37: 9 | I37: 11 | J37: 60.2 | K37: IIMP | L37: MKT | N37: Has implemented the last time's feedback, although has some scope of improvement. , good at ground realities.
A38: 45930.54 | B38: smrutimehadia@gmail.com | C38: Sanchi Shiradhonkar | D38: 16 | E38: 10.6 | F38: 12 | G38: 16 | H38: 10 | I38: 11 | J38: 75.6 | K38: ICP | L38: MKT | N38: Overall good.
A39: 45930.542 | B39: tusharvkshirsagar@gmail.com | C39: Arya Asolkar | D39: 16 | E39: 9 | F39: 12 | G39: 16 | H39: 12 | I39: 12 | J39: 77 | K39: ISBS PGDM | L39: HR | N39: Great communication
A40: 45930.544 | B40: madhumithapalani26@gmail.com | C40: Rajat Ghode | D40: 16 | E40: 12 | F40: 14 | G40: 16 | H40: 12 | I40: 10 | J40: 80 | K40: ISBS PGDM | L40: MKT
...

Sheet Count
A1: Trainer | B1: Count | C1: Type
A2: aishwaryakalyanshetti@gmail.com | B2: =COUNTIF(Technical_Evaluations!B2:B696,A2) -> 35 | C2: Technical
A3: drtasneem.in@gmail.com | B3: =COUNTIF(Technical_Evaluations!B2:B697,A3) -> 7 | C3: Technical
A4: kuldeep.manhas@gmail.com | B4: =COUNTIF(Technical_Evaluations!B2:B698,A4) -> 11 | C4: Technical
A5: prashant2k1@gmail.com | B5: =COUNTIF(Technical_Evaluations!B2:B699,A5) -> 27 | C5: Technical
A6: deodeepa@gmail.com | B6: =COUNTIF(SoftSkills_Evaluations!B2:B603,A6) -> 7 | C6: SoftSkills
A7: madhumithapalani26@gmail.com | B7: =COUNTIF(SoftSkills_Evaluations!B2:B640,A7) -> 22 | C7: SoftSkills
A8: smrutimehadia@gmail.com | B8: =COUNTIF(SoftSkills_Evaluations!B2:B605,A8) -> 31 | C8: SoftSkills
A9: tusharvkshirsagar@gmail.com | B9: =COUNTIF(SoftSkills_Evaluations!B2:B606,A9) -> 15 | C9: SoftSkills

Sheet Interviewers
A1: Email | B1: Password
A2: test@1234.com
A3: madhumithapalani26@gmail.com
A4: tusharvkshirsagar@gmail.com
A5: smrutimehadia@gmail.com
A6: kuldeep.manhas@gmail.com
A7: aishwaryakalyanshetti@gmail.com
A8: deodeepa@gmail.com
A9: drtasneem.in@gmail.com
A10: prashant2k1@gmail.com
A11: apurvafrench@gmail.com

Sheet Student list
C1: Domain | D1: Total
C2: Finance | D2: 63
C3: HR | D3: 8
C4: Marketing | D4: 58
D5: =SUM(D2:D4) -> 129
A7: Sr. No | B7: Name | C7: Email | D7: Campus | E7: Specialization | F7: Soft Skills Score | G7: Technical Score | H7: GD Score | I7: Total Score
A8: 1 | B8: Ved M Vibhute | C8: ved.vibhute@indiraisbs.ac.in | D8: ISBS PGDM | E8: FIN | F8: 93.6 | G8: 95.4 | I8: 94.5
A9: 2 | B9: Piyanshi | C9: piyanshi.chugh@indiraisbs.ac.in | D9: ISBS PGDM | E9: FIN | F9: 81.8 | G9: 93.8 | I9: 87.8
A10: 3 | B10: Gauri Pawansing Thakur | C10: gauri.thakur@indiraisbs.ac.in | D10: ISBS PGDM | E10: HR | F10: 71.6 | G10: 43 | H10: 59 | I10: 86.8
A11: 4 | B11: Neha Jadhav | C11: neha.jadhav24@indiraiimp.edu.in | D11: IIMP | E11: HR | F11: 95 | G11: 83.8 | H11: 67 | I11: 81.93333
A12: 5 | B12: Ankita Sarode | C12: ankita.sarode24@indiraiimp.edu.in | D12: IIMP | E12: MKT | F12: 80 | H12: 82 | I12: 81
A13: 6 | B13: swaleha paliwala | C13: swaleha.paliwala24@indiraiimp.edu.in | D13: IIMP | E13: FIN | F13: 90 | G13: 95 | H13: 58 | I13: 81
A14: 7 | B14: Roshni Kewlani | C14: roshni.kewlani@indiraisbs.edu.in | D14: ISBS | E14: MKT | G14: 67 | H14: 94 | I14: 80.5
A15: 8 | B15: Soham Shashikant Chaudhari | C15: soham.chaudhari24@indiraiimp.edu.in | D15: IIMP | E15: FIN | G15: 89.4 | H15: 71 | I15: 80.2
A16: 9 | B16: Manish Ahire | C16: manishahire@indiraicp.edu.in | D16: ICP | E16: MKT | F16: 74.4 | G16: 89.2 | H16: 76 | I16: 79.86667
A17: 10 | B17: Saumyaa Pathak | C17: saumyaa.pathak@indiraisbs.ac.in | D17: ISBS PGDM | E17: MKT | F17: 92.8 | G17: 79.8 | H17: 64 | I17: 78.86667
A18: 11 | B18: Aditi Sunil Nade | C18: aditi.nade24@indiraiimp.edu.in | D18: IIMP | E18: HR | F18: 96 | G18: 89.4 | H18: 51 | I18: 78.8
A19: 12 | B19: KUSHAL RAMESHWAR MANKAR | C19: kushal.mankar24@indiraiimp.edu.in | D19: IIMP | E19: MKT | F19: 77.6 | G19: 84.2 | H19: 73 | I19: 78.26667
A20: 13 | B20: KUSHAL RAMESHWAR MANKAR | C20: kushal.mankar24@indiraiimp.edu.in | D20: IIMP | E20: MKT | F20: 77.6 | G20: 84.2 | H20: 73 | I20: 78.26667
A21: 14 | B21: srushti sharad pawar | C21: srushti.pawar24@indiraiimp.edu.in | D21: IIMP | E21: MKT | F21: 62.6 | G21: 76.6 | H21: 93 | I21: 77.4
A22: 15 | B22: Omkar Arun Mhaske | C22: omkar.mhaske24@indiraiimp.edu.in | D22: IIMP | E22: MKT | G22: 76.8 | H22: 77 | I22: 76.9
A23: 16 | B23: Arya Asolkar | C23: arya.asolkar@indiraisbs.ac.in | D23: ISBS PGDM | E23: HR | F23: 77 | H23: 76 | I23: 76.5
A24: 17 | B24: Dhriti Sahu | C24: dhriti.sahu@indiraisbs.ac.in | D24: ISBS PGDM | E24: MKT | G24: 87.6 | H24: 64 | I24: 75.8
A25: 18 | B25: Uddesh Anil Panpaliya | C25: uddesh.panpaliya@indiraisbs.edu.in | D25: ISBS | E25: MKT | F25: 64.8 | G25: 77.2 | H25: 85 | I25: 75.66667
A26: 19 | B26: SONALI SOMNATH GAIKAR | C26: sonali.gaikar@indiraisbs.edu.in | D26: ISBS | E26: FIN | F26: 77.6 | G26: 97 | H26: 51 | I26: 75.2
A27: 20 | B27: Toshan Rane | C27: toshan.rane@indiraisbs.ac.in | D27: ISBS PGDM | E27: FIN | G27: 65.8 | H27: 84 | I27: 74.9
A28: 21 | B28: Emmanuel Suresh Mahure | C28: emmanuel.mahure@indiraisbs.edu.in | D28: ISBS | E28: MKT | F28: 72.4 | G28: 84.8 | H28: 67 | I28: 74.73333
A29: 22 | B29: Mehul Kailas Tamboli | C29: mehul.tamboli@indiraisbs.ac.in | D29: ISBS PGDM | E29: FIN | F29: 66.4 | G29: 82.6 | I29: 74.5
A30: 23 | B30: Tanishq Chandrakant Rathod | C30: tanishq.rathod24@indiraiimp.edu.in | D30: IIMP | E30: FIN | G30: 90 | H30: 59 | I30: 74.5
A31: 24 | B31: Vishal Rajendra Gavade | C31: vishal.gavade@indiraisbs.ac.in | D31: ISBS PGDM | E31: MKT | G31: 75.2 | H31: 72 | I31: 73.6
A32: 25 | B32: Sanchi Shiradhonkar | C32: sanchishiradhonkar@indiraicp.edu.in | D32: ICP | E32: MKT | F32: 75.6 | G32: 69 | H32: 76 | I32: 73.53333
A33: 26 | B33: Abha Patil | C33: abha.patil24@indiraiimp.edu.in | D33: IIMP | E33: MKT | F33: 66 | G33: 80 | H33: 73 | I33: 73
A34: 27 | B34: Kaustubh Pundlik Gawale | C34: kaustubhgawale@indiraicp.edu.in | D34: ICP | E34: FIN | F34: 72.4 | G34: 96 | H34: 50 | I34: 72.8
A35: 28 | B35: Rohini Ravindra Kamble | C35: rohini.kamble@indiraisbs.edu.in | D35: ISBS | E35: MKT | G35: 65.2 | H35: 80 | I35: 72.6
A36: 29 | B36: Shekhar Jena | C36: shekhar.jena@indiraisbs.ac.in | D36: ISBS PGDM | E36: MKT | F36: 62.6 | G36: 76 | H36: 78 | I36: 72.2
A37: 30 | B37: Bhavesh Dilip Jagtap | C37: bhavesh.jagtap24@indiraiimp.edu.in | D37: IIMP | E37: FIN | F37: 85.8 | G37: 80.4 | H37: 50 | I37: 72.06667
A38: 31 | B38: Prathamesh jaiswal | C38: prathamesh.jaiswal@indiraisbs.ac.in | D38: ISBS PGDM | E38: MKT | F38: 82 | G38: 71 | H38: 57 | I38: 70
A39: 32 | B39: Samrudh Dnyaneshwar Somase | C39: samrudhomase@indiraicp.edu.in | D39: ICP | E39: MKT | F39: 70.4 | G39: 80.6 | H39: 59 | I39: 70
A40: 33 | B40: Gorgile rushikesh chandrakant | C40: rushikesh.gorgile24@indiraiimp.edu.in | D40: IIMP | E40: MKT | F40: 67 | G40: 71 | H40: 71 | I40: 69.66667
A41: 34 | B41: Rasika Rajendra Gawali | C41: rasika.gawali24@indiraiimp.edu.in | D41: IIMP | E41: HR | F41: 69.2 | G41: 77 | H41: 61 | I41: 69.06667
...

Sheet Sheet9
B2: Name | C2: Email | D2: Campus | E2: Specialization | F2: Total Score Overall
A3: 1 | B3: Neha Jadhav | C3: neha.jadhav24@indiraiimp.edu.in | D3: IIMP | E3: HR | F3: 81.933333
A4: 2 | B4: swaleha paliwala | C4: swaleha.paliwala24@indiraiimp.edu.in | D4: IIMP | E4: FIN | F4: 81
A5: 3 | B5: Manish Ahire | C5: manishahire@indiraicp.edu.in | D5: ICP | E5: MKT | F5: 79.866667
A6: 4 | B6: Saumyaa Pathak | C6: saumyaa.pathak@indiraisbs.ac.in | D6: ISBS PGDM | E6: MKT | F6: 78.866667
A7: 5 | B7: Aditi Sunil Nade | C7: aditi.nade24@indiraiimp.edu.in | D7: IIMP | E7: HR | F7: 78.8
A8: 6 | B8: KUSHAL RAMESHWAR MANKAR | C8: kushal.mankar24@indiraiimp.edu.in | D8: IIMP | E8: MKT | F8: 78.266667
A9: 7 | B9: KUSHAL RAMESHWAR MANKAR | C9: kushal.mankar24@indiraiimp.edu.in | D9: IIMP | E9: MKT | F9: 78.266667
A10: 8 | B10: srushti sharad pawar | C10: srushti.pawar24@indiraiimp.edu.in | D10: IIMP | E10: MKT | F10: 77.4
A11: 9 | B11: Uddesh Anil Panpaliya | C11: uddesh.panpaliya@indiraisbs.edu.in | D11: ISBS | E11: MKT | F11: 75.666667
A12: 10 | B12: SONALI SOMNATH GAIKAR | C12: sonali.gaikar@indiraisbs.edu.in | D12: ISBS | E12: FIN | F12: 75.2
A13: 11 | B13: Emmanuel Suresh Mahure | C13: emmanuel.mahure@indiraisbs.edu.in | D13: ISBS | E13: MKT | F13: 74.733333
A14: 12 | B14: Sanchi Shiradhonkar | C14: sanchishiradhonkar@indiraicp.edu.in | D14: ICP | E14: MKT | F14: 73.533333
... A36: 34 | B36: Gaurav Ashok Pawar | C36: gaurav.pawar24@indiraiimp.edu.in | D36: IIMP | E36: FIN | F36: 59.8
B37: Name | C37: Email | D37: Campus | E37: Specialization | F37: Total Score SS + GD
A38: 1 | B38: Ankita Sarode | C38: ankita.sarode24@indiraiimp.edu.in | D38: IIMP | E38: MKT | F38: 81
A39: 2 | B39: Neha Jadhav | C39: neha.jadhav24@indiraiimp.edu.in | D39: IIMP | E39: HR | F39: 81
A40: 3 | B40: Saumyaa Pathak | C40: saumyaa.pathak@indiraisbs.ac.in | D40: ISBS PGDM | E40: MKT | F40: 78.4
A41: 4 | B41: Rajat Ghode | C41: rajat.ghode@indiraisbs.ac.in | D41: ISBS PGDM | E41: MKT | F41: 78
A42: 5 | B42: srushti sharad pawar | C42: srushti.pawar24@indiraiimp.edu.in | D42: IIMP | E42: MKT | F42: 77.8
A43: 6 | B43: Sakshi Deulkar | C43: sakshi.deulkar@indiraisbs.ac.in | D43: ISBS PGDM | E43: MKT | F43: 77.8
A44: 7 | B44: Arya Asolkar | C44: arya.asolkar@indiraisbs.ac.in | D44: ISBS PGDM | E44: HR | F44: 76.5
A45: 8 | B45: Sanchi Shiradhonkar | C45: sanchishiradhonkar@indiraicp.edu.in | D45: ICP | E45: MKT | F45: 75.8
A46: 9 | B46: KUSHAL RAMESHWAR MANKAR | C46: kushal.mankar24@indiraiimp.edu.in | D46: IIMP | E46: MKT | F46: 75.3
A47: 10 | B47: KUSHAL RAMESHWAR MANKAR | C47: kushal.mankar24@indiraiimp.edu.in | D47: IIMP | E47: MKT | F47: 75.3
A48: 11 | B48: Manish Ahire | C48: manishahire@indiraicp.edu.in | D48: ICP | E48: MKT | F48: 75.2
A49: 12 | B49: Uddesh Anil Panpaliya | C49: uddesh.panpaliya@indiraisbs.edu.in | D49: ISBS | E49: MKT | F49: 74.9
... A79: 42 | B79: Onkar Sanjay Khandade | C79: onkar.khandade24@indiraiimp.edu.in | D79: IIMP | E79: MKT | F79: 58
B80: Name | C80: Email | D80: Campus | E80: Specialization | F80: Technical Score
A81: 1 | B81: SONALI SOMNATH GAIKAR | C81: sonali.gaikar@indiraisbs.edu.in | D81: ISBS | E81: FIN | F81: 97
A82: 2 | B82: Kaustubh Pundlik Gawale | C82: kaustubhgawale@indiraicp.edu.in | D82: ICP | E82: FIN | F82: 96
A83: 3 | B83: Ved M Vibhute | C83: ved.vibhute@indiraisbs.ac.in | D83: ISBS PGDM | E83: FIN | F83: 95.4
A84: 4 | B84: swaleha paliwala | C84: swaleha.paliwala24@indiraiimp.edu.in | D84: IIMP | E84: FIN | F84: 95
A85: 5 | B85: Sachi Akshay Arora | C85: sachi.arora@indiraisbs.ac.in | D85: ISBS PGDM | E85: FIN | F85: 94.2
A86: 6 | B86: Piyanshi | C86: piyanshi.chugh@indiraisbs.ac.in | D86: ISBS PGDM | E86: FIN | F86: 93.8
A87: 7 | B87: PRATIKSHA YUVRAJ SAYAM | C87: pratiksha.sayam@indiraisbs.edu.in | D87: ISBS | E87: FIN | F87: 92.6
A88: 8 | B88: Nikita Sharma | C88: nikita.sharma@indiraisbs.ac.in | D88: ISBS PGDM | E88: FIN | F88: 92.4
A89: 9 | B89: Vaishnavi Shrikant Pahune | C89: vaishnavi.pahune24@indiraiimp.edu.in | D89: IIMP | E89: MKT | F89: 91.8
A90: 10 | B90: Tanishq Chandrakant Rathod | C90: tanishq.rathod24@indiraiimp.edu.in | D90: IIMP | E90: FIN | F90: 90
A91: 11 | B91: Soumil Kailas Salunke | C91: soumilsalunke@indiraicp.edu.in | D91: ISBS PGDM | E91: FIN | F91: 89.8
...

Sheet Compiled List
A1: Overall Rating Student List
A2: Sr. No | B2: Name | C2: Email | D2: Campus | E2: Specialization | F2: Total Score Overall
A3: 1 | B3: Neha Jadhav | C3: neha.jadhav24@indiraiimp.edu.in | D3: IIMP | E3: HR | F3: 81.933333
A4: 2 | B4: swaleha paliwala | C4: swaleha.paliwala24@indiraiimp.edu.in | D4: IIMP | E4: FIN | F4: 81
A5: 3 | B5: Manish Ahire | C5: manishahire@indiraicp.edu.in | D5: ICP | E5: MKT | F5: 79.866667
A6: 4 | B6: Saumyaa Pathak | C6: saumyaa.pathak@indiraisbs.ac.in | D6: ISBS PGDM | E6: MKT | F6: 78.866667
A7: 5 | B7: Aditi Sunil Nade | C7: aditi.nade24@indiraiimp.edu.in | D7: IIMP | E7: HR | F7: 78.8
A8: 6 | B8: KUSHAL RAMESHWAR MANKAR | C8: kushal.mankar24@indiraiimp.edu.in | D8: IIMP | E8: MKT | F8: 78.266667
A9: 7 | B9: srushti sharad pawar | C9: srushti.pawar24@indiraiimp.edu.in | D9: IIMP | E9: MKT | F9: 77.4
A10: 8 | B10: Uddesh Anil Panpaliya | C10: uddesh.panpaliya@indiraisbs.edu.in | D10: ISBS | E10: MKT | F10: 75.666667
A11: 9 | B11: SONALI SOMNATH GAIKAR | C11: sonali.gaikar@indiraisbs.edu.in | D11: ISBS | E11: FIN | F11: 75.2
A12: 10 | B12: Emmanuel Suresh Mahure | C12: emmanuel.mahure@indiraisbs.edu.in | D12: ISBS | E12: MKT | F12: 74.733333
A13: 11 | B13: Sanchi Shiradhonkar | C13: sanchishiradhonkar@indiraicp.edu.in | D13: ICP | E13: MKT | F13: 73.533333
A14: 12 | B14: Abha Patil | C14: abha.patil24@indiraiimp.edu.in | D14: IIMP | E14: MKT | F14: 73
... A35: 33 | B35: Gaurav Ashok Pawar | C35: gaurav.pawar24@indiraiimp.edu.in | D35: IIMP | E35: FIN | F35: 59.8
A36: Communication Studnets List
A37: Sr. No | B37: Name | C37: Email | D37: Campus | E37: Specialization | F37: Total Score ( SS + GD )
A38: 1 | B38: Ankita Sarode | C38: ankita.sarode24@indiraiimp.edu.in | D38: IIMP | E38: MKT | F38: 81
A39: 2 | B39: Sakshi Deulkar | C39: sakshi.deulkar@indiraisbs.ac.in | D39: ISBS PGDM | E39: MKT | F39: 77.8
A40: 3 | B40: Arya Asolkar | C40: arya.asolkar@indiraisbs.ac.in | D40: ISBS PGDM | E40: HR | F40: 76.5
A41: 4 | B41: Utkarsh Mohan Deshmukh | C41: utkarsh.deshmukh@indiraisbs.ac.in | D41: ISBS PGDM | E41: MKT | F41: 69.5
A42: 5 | B42: Pratik Shivaji Ghuge | C42: pratik.ghuge24@indiraiimp.edu.in | D42: IIMP | E42: MKT | F42: 69
A43: 6 | B43: Janhavi Mahadeo Chaware | C43: janhavichaware@indiraicp.edu.in | D43: ICP | E43: MKT | F43: 67.6
A44: 7 | B44: Pratik Vasant Ekale | C44: pratik.ekale24@indiraiimp.edu.in | D44: IIMP | E44: FIN | F44: 67.5
A45: 8 | B45: Shivam Singh | C45: shivam.singh@indiraisbs.ac.in | D45: ISBS PGDM | E45: MKT | F45: 65.8
A46: 9 | B46: Gauri Pawansing Thakur | C46: gauri.thakur@indiraisbs.ac.in | D46: ISBS PGDM | E46: HR | F46: 65.3
A47: 10 | B47: Sahil Dilip Tijare | C47: sahil.tijare24@indiraiimp.edu.in | D47: IIMP | E47: MKT | F47: 62.2
A48: 11 | B48: Amit Satish Bodake | C48: amit.bodake24@indiraiimp.edu.in | D48: IIMP | E48: MKT | F48: 60.8
A49: 12 | B49: Onkar Sanjay Khandade | C49: onkar.khandade24@indiraiimp.edu.in | D49: IIMP | E49: MKT | F49: 58
A51: Technical Student list
A52: Sr. No | B52: Name | C52: Email | D52: Campus | E52: Specialization | F52: Total Score ( Technical )
A53: 1 | B53: Sachi Akshay Arora | C53: sachi.arora@indiraisbs.ac.in | D53: ISBS PGDM | E53: FIN | F53: 94.2
A54: 2 | B54: Piyanshi | C54: piyanshi.chugh@indiraisbs.ac.in | D54: ISBS PGDM | E54: FIN | F54: 93.8
A55: 3 | B55: PRATIKSHA YUVRAJ SAYAM | C55: pratiksha.sayam@indiraisbs.edu.in | D55: ISBS | E55: FIN | F55: 92.6
A56: 4 | B56: Nikita Sharma | C56: nikita.sharma@indiraisbs.ac.in | D56: ISBS PGDM | E56: FIN | F56: 92.4
A57: 5 | B57: Tanishq Chandrakant Rathod | C57: tanishq.rathod24@indiraiimp.edu.in | D57: IIMP | E57: FIN | F57: 90
A58: 6 | B58: Soumil Kailas Salunke | C58: soumilsalunke@indiraicp.edu.in | D58: ISBS PGDM | E58: FIN | F58: 89.8
A59: 7 | B59: Soham Shashikant Chaudhari | C59: soham.chaudhari24@indiraiimp.edu.in | D59: IIMP | E59: FIN | F59: 89.4
A60: 8 | B60: Ayush Jain | C60: ayush.jain2426@indiraisbs.ac.in | D60: ISBS PGDM | E60: FIN | F60: 89
A61: 9 | B61: Dhriti Sahu | C61: dhriti.sahu@indiraisbs.ac.in | D61: ISBS PGDM | E61: MKT | F61: 87.6
...
